[32mINFO    [0m utilities.custom_Logger:test_login.py:38 **************** login with invalid credentials -----started ******************
[32mINFO    [0m utilities.custom_Logger:test_login.py:47 *************** login with invalid credentials test case is passed ****************